[2024-02-21T07:44:45.083+0000] {taskinstance.py:1956} INFO - Dependencies all met for dep_context=non-requeueable deps ti=<TaskInstance: extract_email.get_mail manual__2024-02-21T07:44:39.827684+00:00 [queued]>
[2024-02-21T07:44:45.093+0000] {taskinstance.py:1956} INFO - Dependencies all met for dep_context=requeueable deps ti=<TaskInstance: extract_email.get_mail manual__2024-02-21T07:44:39.827684+00:00 [queued]>
[2024-02-21T07:44:45.094+0000] {taskinstance.py:2170} INFO - Starting attempt 1 of 1
[2024-02-21T07:44:45.109+0000] {taskinstance.py:2191} INFO - Executing <Task(PythonOperator): get_mail> on 2024-02-21 07:44:39.827684+00:00
[2024-02-21T07:44:45.114+0000] {standard_task_runner.py:60} INFO - Started process 77 to run task
[2024-02-21T07:44:45.117+0000] {standard_task_runner.py:87} INFO - Running: ['***', 'tasks', 'run', 'extract_email', 'get_mail', 'manual__2024-02-21T07:44:39.827684+00:00', '--job-id', '95', '--raw', '--subdir', 'DAGS_FOLDER/extract_email.py', '--cfg-path', '/tmp/tmpvcc2hl0r']
[2024-02-21T07:44:45.120+0000] {standard_task_runner.py:88} INFO - Job 95: Subtask get_mail
[2024-02-21T07:44:45.158+0000] {task_command.py:423} INFO - Running <TaskInstance: extract_email.get_mail manual__2024-02-21T07:44:39.827684+00:00 [running]> on host 9bab6a0db245
[2024-02-21T07:44:45.243+0000] {taskinstance.py:2480} INFO - Exporting env vars: AIRFLOW_CTX_DAG_OWNER='***' AIRFLOW_CTX_DAG_ID='extract_email' AIRFLOW_CTX_TASK_ID='get_mail' AIRFLOW_CTX_EXECUTION_DATE='2024-02-21T07:44:39.827684+00:00' AIRFLOW_CTX_TRY_NUMBER='1' AIRFLOW_CTX_DAG_RUN_ID='manual__2024-02-21T07:44:39.827684+00:00'
[2024-02-21T07:44:45.244+0000] {taskinstance.py:2698} ERROR - Task failed with exception
Traceback (most recent call last):
  File "/home/airflow/.local/lib/python3.8/site-packages/airflow/models/taskinstance.py", line 433, in _execute_task
    result = execute_callable(context=context, **execute_callable_kwargs)
  File "/home/airflow/.local/lib/python3.8/site-packages/airflow/operators/python.py", line 196, in execute
    context_merge(context, self.op_kwargs, templates_dict=self.templates_dict)
  File "/home/airflow/.local/lib/python3.8/site-packages/airflow/utils/context.py", line 261, in context_merge
    context.update(*args, **kwargs)
  File "/usr/local/lib/python3.8/_collections_abc.py", line 837, in update
    for key, value in other:
ValueError: too many values to unpack (expected 2)
[2024-02-21T07:44:45.254+0000] {taskinstance.py:1138} INFO - Marking task as FAILED. dag_id=extract_email, task_id=get_mail, execution_date=20240221T074439, start_date=20240221T074445, end_date=20240221T074445
[2024-02-21T07:44:45.270+0000] {standard_task_runner.py:107} ERROR - Failed to execute job 95 for task get_mail (too many values to unpack (expected 2); 77)
[2024-02-21T07:44:45.289+0000] {local_task_job_runner.py:234} INFO - Task exited with return code 1
[2024-02-21T07:44:45.318+0000] {taskinstance.py:3280} INFO - 0 downstream tasks scheduled from follow-on schedule check
