[2024-02-21T07:37:49.257+0000] {taskinstance.py:1956} INFO - Dependencies all met for dep_context=non-requeueable deps ti=<TaskInstance: extract_email.get_mail scheduled__2024-01-25T00:00:00+00:00 [queued]>
[2024-02-21T07:37:49.282+0000] {taskinstance.py:1956} INFO - Dependencies all met for dep_context=requeueable deps ti=<TaskInstance: extract_email.get_mail scheduled__2024-01-25T00:00:00+00:00 [queued]>
[2024-02-21T07:37:49.283+0000] {taskinstance.py:2170} INFO - Starting attempt 1 of 1
[2024-02-21T07:37:49.308+0000] {taskinstance.py:2191} INFO - Executing <Task(PythonOperator): get_mail> on 2024-01-25 00:00:00+00:00
[2024-02-21T07:37:49.317+0000] {standard_task_runner.py:60} INFO - Started process 68 to run task
[2024-02-21T07:37:49.328+0000] {standard_task_runner.py:87} INFO - Running: ['***', 'tasks', 'run', 'extract_email', 'get_mail', 'scheduled__2024-01-25T00:00:00+00:00', '--job-id', '58', '--raw', '--subdir', 'DAGS_FOLDER/extract_email.py', '--cfg-path', '/tmp/tmptpmtzlrk']
[2024-02-21T07:37:49.331+0000] {standard_task_runner.py:88} INFO - Job 58: Subtask get_mail
[2024-02-21T07:37:49.513+0000] {task_command.py:423} INFO - Running <TaskInstance: extract_email.get_mail scheduled__2024-01-25T00:00:00+00:00 [running]> on host 893865381b0d
[2024-02-21T07:37:49.813+0000] {taskinstance.py:2480} INFO - Exporting env vars: AIRFLOW_CTX_DAG_OWNER='***' AIRFLOW_CTX_DAG_ID='extract_email' AIRFLOW_CTX_TASK_ID='get_mail' AIRFLOW_CTX_EXECUTION_DATE='2024-01-25T00:00:00+00:00' AIRFLOW_CTX_TRY_NUMBER='1' AIRFLOW_CTX_DAG_RUN_ID='scheduled__2024-01-25T00:00:00+00:00'
[2024-02-21T07:37:49.815+0000] {taskinstance.py:2698} ERROR - Task failed with exception
Traceback (most recent call last):
  File "/home/airflow/.local/lib/python3.8/site-packages/airflow/models/taskinstance.py", line 433, in _execute_task
    result = execute_callable(context=context, **execute_callable_kwargs)
  File "/home/airflow/.local/lib/python3.8/site-packages/airflow/operators/python.py", line 196, in execute
    context_merge(context, self.op_kwargs, templates_dict=self.templates_dict)
  File "/home/airflow/.local/lib/python3.8/site-packages/airflow/utils/context.py", line 261, in context_merge
    context.update(*args, **kwargs)
  File "/usr/local/lib/python3.8/_collections_abc.py", line 837, in update
    for key, value in other:
ValueError: too many values to unpack (expected 2)
[2024-02-21T07:37:49.865+0000] {taskinstance.py:1138} INFO - Marking task as FAILED. dag_id=extract_email, task_id=get_mail, execution_date=20240125T000000, start_date=20240221T073749, end_date=20240221T073749
[2024-02-21T07:37:49.966+0000] {standard_task_runner.py:107} ERROR - Failed to execute job 58 for task get_mail (too many values to unpack (expected 2); 68)
[2024-02-21T07:37:49.995+0000] {local_task_job_runner.py:234} INFO - Task exited with return code 1
[2024-02-21T07:37:50.073+0000] {taskinstance.py:3280} INFO - 0 downstream tasks scheduled from follow-on schedule check
[2024-02-21T07:59:30.479+0000] {taskinstance.py:1956} INFO - Dependencies all met for dep_context=non-requeueable deps ti=<TaskInstance: extract_email.get_mail scheduled__2024-01-25T00:00:00+00:00 [queued]>
[2024-02-21T07:59:30.488+0000] {taskinstance.py:1956} INFO - Dependencies all met for dep_context=requeueable deps ti=<TaskInstance: extract_email.get_mail scheduled__2024-01-25T00:00:00+00:00 [queued]>
[2024-02-21T07:59:30.488+0000] {taskinstance.py:2170} INFO - Starting attempt 1 of 1
[2024-02-21T07:59:30.500+0000] {taskinstance.py:2191} INFO - Executing <Task(PythonOperator): get_mail> on 2024-01-25 00:00:00+00:00
[2024-02-21T07:59:30.504+0000] {standard_task_runner.py:60} INFO - Started process 351 to run task
[2024-02-21T07:59:30.506+0000] {standard_task_runner.py:87} INFO - Running: ['***', 'tasks', 'run', 'extract_email', 'get_mail', 'scheduled__2024-01-25T00:00:00+00:00', '--job-id', '122', '--raw', '--subdir', 'DAGS_FOLDER/extract_email.py', '--cfg-path', '/tmp/tmpx8z6fpg8']
[2024-02-21T07:59:30.508+0000] {standard_task_runner.py:88} INFO - Job 122: Subtask get_mail
[2024-02-21T07:59:30.540+0000] {task_command.py:423} INFO - Running <TaskInstance: extract_email.get_mail scheduled__2024-01-25T00:00:00+00:00 [running]> on host 9bab6a0db245
[2024-02-21T07:59:30.598+0000] {taskinstance.py:2480} INFO - Exporting env vars: AIRFLOW_CTX_DAG_OWNER='***' AIRFLOW_CTX_DAG_ID='extract_email' AIRFLOW_CTX_TASK_ID='get_mail' AIRFLOW_CTX_EXECUTION_DATE='2024-01-25T00:00:00+00:00' AIRFLOW_CTX_TRY_NUMBER='1' AIRFLOW_CTX_DAG_RUN_ID='scheduled__2024-01-25T00:00:00+00:00'
[2024-02-21T07:59:32.738+0000] {taskinstance.py:2698} ERROR - Task failed with exception
Traceback (most recent call last):
  File "/home/airflow/.local/lib/python3.8/site-packages/airflow/models/taskinstance.py", line 433, in _execute_task
    result = execute_callable(context=context, **execute_callable_kwargs)
  File "/home/airflow/.local/lib/python3.8/site-packages/airflow/operators/python.py", line 199, in execute
    return_value = self.execute_callable()
  File "/home/airflow/.local/lib/python3.8/site-packages/airflow/operators/python.py", line 216, in execute_callable
    return self.python_callable(*self.op_args, **self.op_kwargs)
  File "/opt/airflow/dags/extract_email.py", line 16, in get_mail
    mail.authorize(account=os.getenv("GMAIL_ACCOUNT"), password=os.getenv("GMAIL_PASSWORD"))
  File "/home/airflow/.local/lib/python3.8/site-packages/RPA/Email/ImapSmtp.py", line 496, in authorize
    self.authorize_imap(
  File "/home/airflow/.local/lib/python3.8/site-packages/RPA/Email/ImapSmtp.py", line 453, in authorize_imap
    self.imap_conn.login(account, password)
  File "/usr/local/lib/python3.8/imaplib.py", line 603, in login
    raise self.error(dat[-1])
imaplib.IMAP4.error: b'[ALERT] Too many simultaneous connections. (Failure)'
[2024-02-21T07:59:32.749+0000] {taskinstance.py:1138} INFO - Marking task as FAILED. dag_id=extract_email, task_id=get_mail, execution_date=20240125T000000, start_date=20240221T075930, end_date=20240221T075932
[2024-02-21T07:59:32.759+0000] {standard_task_runner.py:107} ERROR - Failed to execute job 122 for task get_mail (b'[ALERT] Too many simultaneous connections. (Failure)'; 351)
[2024-02-21T07:59:32.771+0000] {local_task_job_runner.py:234} INFO - Task exited with return code 1
[2024-02-21T07:59:32.786+0000] {taskinstance.py:3280} INFO - 0 downstream tasks scheduled from follow-on schedule check
