[2024-02-21T07:38:17.628+0000] {taskinstance.py:1956} INFO - Dependencies all met for dep_context=non-requeueable deps ti=<TaskInstance: extract_email.get_mail scheduled__2024-02-16T00:00:00+00:00 [queued]>
[2024-02-21T07:38:17.644+0000] {taskinstance.py:1956} INFO - Dependencies all met for dep_context=requeueable deps ti=<TaskInstance: extract_email.get_mail scheduled__2024-02-16T00:00:00+00:00 [queued]>
[2024-02-21T07:38:17.645+0000] {taskinstance.py:2170} INFO - Starting attempt 1 of 1
[2024-02-21T07:38:17.659+0000] {taskinstance.py:2191} INFO - Executing <Task(PythonOperator): get_mail> on 2024-02-16 00:00:00+00:00
[2024-02-21T07:38:17.666+0000] {standard_task_runner.py:60} INFO - Started process 128 to run task
[2024-02-21T07:38:17.669+0000] {standard_task_runner.py:87} INFO - Running: ['***', 'tasks', 'run', 'extract_email', 'get_mail', 'scheduled__2024-02-16T00:00:00+00:00', '--job-id', '89', '--raw', '--subdir', 'DAGS_FOLDER/extract_email.py', '--cfg-path', '/tmp/tmpf2jl6z8f']
[2024-02-21T07:38:17.671+0000] {standard_task_runner.py:88} INFO - Job 89: Subtask get_mail
[2024-02-21T07:38:17.720+0000] {task_command.py:423} INFO - Running <TaskInstance: extract_email.get_mail scheduled__2024-02-16T00:00:00+00:00 [running]> on host 893865381b0d
[2024-02-21T07:38:17.794+0000] {taskinstance.py:2480} INFO - Exporting env vars: AIRFLOW_CTX_DAG_OWNER='***' AIRFLOW_CTX_DAG_ID='extract_email' AIRFLOW_CTX_TASK_ID='get_mail' AIRFLOW_CTX_EXECUTION_DATE='2024-02-16T00:00:00+00:00' AIRFLOW_CTX_TRY_NUMBER='1' AIRFLOW_CTX_DAG_RUN_ID='scheduled__2024-02-16T00:00:00+00:00'
[2024-02-21T07:38:17.795+0000] {taskinstance.py:2698} ERROR - Task failed with exception
Traceback (most recent call last):
  File "/home/airflow/.local/lib/python3.8/site-packages/airflow/models/taskinstance.py", line 433, in _execute_task
    result = execute_callable(context=context, **execute_callable_kwargs)
  File "/home/airflow/.local/lib/python3.8/site-packages/airflow/operators/python.py", line 196, in execute
    context_merge(context, self.op_kwargs, templates_dict=self.templates_dict)
  File "/home/airflow/.local/lib/python3.8/site-packages/airflow/utils/context.py", line 261, in context_merge
    context.update(*args, **kwargs)
  File "/usr/local/lib/python3.8/_collections_abc.py", line 837, in update
    for key, value in other:
ValueError: too many values to unpack (expected 2)
[2024-02-21T07:38:17.802+0000] {taskinstance.py:1138} INFO - Marking task as FAILED. dag_id=extract_email, task_id=get_mail, execution_date=20240216T000000, start_date=20240221T073817, end_date=20240221T073817
[2024-02-21T07:38:17.812+0000] {standard_task_runner.py:107} ERROR - Failed to execute job 89 for task get_mail (too many values to unpack (expected 2); 128)
[2024-02-21T07:38:17.841+0000] {local_task_job_runner.py:234} INFO - Task exited with return code 1
[2024-02-21T07:38:17.856+0000] {taskinstance.py:3280} INFO - 0 downstream tasks scheduled from follow-on schedule check
[2024-02-21T08:00:04.807+0000] {taskinstance.py:1956} INFO - Dependencies all met for dep_context=non-requeueable deps ti=<TaskInstance: extract_email.get_mail scheduled__2024-02-16T00:00:00+00:00 [queued]>
[2024-02-21T08:00:04.814+0000] {taskinstance.py:1956} INFO - Dependencies all met for dep_context=requeueable deps ti=<TaskInstance: extract_email.get_mail scheduled__2024-02-16T00:00:00+00:00 [queued]>
[2024-02-21T08:00:04.814+0000] {taskinstance.py:2170} INFO - Starting attempt 1 of 1
[2024-02-21T08:00:04.824+0000] {taskinstance.py:2191} INFO - Executing <Task(PythonOperator): get_mail> on 2024-02-16 00:00:00+00:00
[2024-02-21T08:00:04.828+0000] {standard_task_runner.py:60} INFO - Started process 404 to run task
[2024-02-21T08:00:04.831+0000] {standard_task_runner.py:87} INFO - Running: ['***', 'tasks', 'run', 'extract_email', 'get_mail', 'scheduled__2024-02-16T00:00:00+00:00', '--job-id', '145', '--raw', '--subdir', 'DAGS_FOLDER/extract_email.py', '--cfg-path', '/tmp/tmpucuy8w2h']
[2024-02-21T08:00:04.832+0000] {standard_task_runner.py:88} INFO - Job 145: Subtask get_mail
[2024-02-21T08:00:04.866+0000] {task_command.py:423} INFO - Running <TaskInstance: extract_email.get_mail scheduled__2024-02-16T00:00:00+00:00 [running]> on host 9bab6a0db245
[2024-02-21T08:00:04.930+0000] {taskinstance.py:2480} INFO - Exporting env vars: AIRFLOW_CTX_DAG_OWNER='***' AIRFLOW_CTX_DAG_ID='extract_email' AIRFLOW_CTX_TASK_ID='get_mail' AIRFLOW_CTX_EXECUTION_DATE='2024-02-16T00:00:00+00:00' AIRFLOW_CTX_TRY_NUMBER='1' AIRFLOW_CTX_DAG_RUN_ID='scheduled__2024-02-16T00:00:00+00:00'
[2024-02-21T08:00:07.549+0000] {taskinstance.py:2698} ERROR - Task failed with exception
Traceback (most recent call last):
  File "/home/airflow/.local/lib/python3.8/site-packages/airflow/models/taskinstance.py", line 433, in _execute_task
    result = execute_callable(context=context, **execute_callable_kwargs)
  File "/home/airflow/.local/lib/python3.8/site-packages/airflow/operators/python.py", line 199, in execute
    return_value = self.execute_callable()
  File "/home/airflow/.local/lib/python3.8/site-packages/airflow/operators/python.py", line 216, in execute_callable
    return self.python_callable(*self.op_args, **self.op_kwargs)
  File "/opt/airflow/dags/extract_email.py", line 16, in get_mail
    mail.authorize(account=os.getenv("GMAIL_ACCOUNT"), password=os.getenv("GMAIL_PASSWORD"))
  File "/home/airflow/.local/lib/python3.8/site-packages/RPA/Email/ImapSmtp.py", line 496, in authorize
    self.authorize_imap(
  File "/home/airflow/.local/lib/python3.8/site-packages/RPA/Email/ImapSmtp.py", line 453, in authorize_imap
    self.imap_conn.login(account, password)
  File "/usr/local/lib/python3.8/imaplib.py", line 603, in login
    raise self.error(dat[-1])
imaplib.IMAP4.error: b'[ALERT] Too many simultaneous connections. (Failure)'
[2024-02-21T08:00:07.570+0000] {taskinstance.py:1138} INFO - Marking task as FAILED. dag_id=extract_email, task_id=get_mail, execution_date=20240216T000000, start_date=20240221T080004, end_date=20240221T080007
[2024-02-21T08:00:07.586+0000] {standard_task_runner.py:107} ERROR - Failed to execute job 145 for task get_mail (b'[ALERT] Too many simultaneous connections. (Failure)'; 404)
[2024-02-21T08:00:07.621+0000] {local_task_job_runner.py:234} INFO - Task exited with return code 1
[2024-02-21T08:00:07.633+0000] {taskinstance.py:3280} INFO - 0 downstream tasks scheduled from follow-on schedule check
