[2024-02-22T03:48:40.654+0000] {taskinstance.py:1956} INFO - Dependencies all met for dep_context=non-requeueable deps ti=<TaskInstance: extract_email.get_mail manual__2024-02-22T03:48:36.889396+00:00 [queued]>
[2024-02-22T03:48:40.668+0000] {taskinstance.py:1956} INFO - Dependencies all met for dep_context=requeueable deps ti=<TaskInstance: extract_email.get_mail manual__2024-02-22T03:48:36.889396+00:00 [queued]>
[2024-02-22T03:48:40.669+0000] {taskinstance.py:2170} INFO - Starting attempt 1 of 1
[2024-02-22T03:48:40.682+0000] {taskinstance.py:2191} INFO - Executing <Task(PythonOperator): get_mail> on 2024-02-22 03:48:36.889396+00:00
[2024-02-22T03:48:40.688+0000] {standard_task_runner.py:60} INFO - Started process 346 to run task
[2024-02-22T03:48:40.690+0000] {standard_task_runner.py:87} INFO - Running: ['***', 'tasks', 'run', 'extract_email', 'get_mail', 'manual__2024-02-22T03:48:36.889396+00:00', '--job-id', '306', '--raw', '--subdir', 'DAGS_FOLDER/extract_email.py', '--cfg-path', '/tmp/tmpfqzvxlgl']
[2024-02-22T03:48:40.693+0000] {standard_task_runner.py:88} INFO - Job 306: Subtask get_mail
[2024-02-22T03:48:40.731+0000] {task_command.py:423} INFO - Running <TaskInstance: extract_email.get_mail manual__2024-02-22T03:48:36.889396+00:00 [running]> on host e849c64d3231
[2024-02-22T03:48:40.786+0000] {taskinstance.py:2480} INFO - Exporting env vars: AIRFLOW_CTX_DAG_OWNER='***' AIRFLOW_CTX_DAG_ID='extract_email' AIRFLOW_CTX_TASK_ID='get_mail' AIRFLOW_CTX_EXECUTION_DATE='2024-02-22T03:48:36.889396+00:00' AIRFLOW_CTX_TRY_NUMBER='1' AIRFLOW_CTX_DAG_RUN_ID='manual__2024-02-22T03:48:36.889396+00:00'
[2024-02-22T03:48:44.245+0000] {ImapSmtp.py:839} INFO - IMAP search: 'gmail:'Message from RPA Python' after:15-12-2023'
[2024-02-22T03:48:49.300+0000] {ImapSmtp.py:1240} INFO - Attachment filepath: PosixPath('attachments/test.txt')
[2024-02-22T03:48:49.301+0000] {ImapSmtp.py:1243} INFO - Saving attachment: test.txt
[2024-02-22T03:48:49.302+0000] {taskinstance.py:2698} ERROR - Task failed with exception
Traceback (most recent call last):
  File "/home/airflow/.local/lib/python3.8/site-packages/airflow/models/taskinstance.py", line 433, in _execute_task
    result = execute_callable(context=context, **execute_callable_kwargs)
  File "/home/airflow/.local/lib/python3.8/site-packages/airflow/operators/python.py", line 199, in execute
    return_value = self.execute_callable()
  File "/home/airflow/.local/lib/python3.8/site-packages/airflow/operators/python.py", line 216, in execute_callable
    return self.python_callable(*self.op_args, **self.op_kwargs)
  File "/opt/airflow/dags/extract_email.py", line 30, in get_mails_content
    attachment = mail.save_attachment(message=m["Message"], target_folder="./attachments/", overwrite=False)
  File "/home/airflow/.local/lib/python3.8/site-packages/RPA/Email/ImapSmtp.py", line 1223, in save_attachment
    return self._save_attachment(message, target_folder, overwrite, prefix)
  File "/home/airflow/.local/lib/python3.8/site-packages/RPA/Email/ImapSmtp.py", line 1247, in _save_attachment
    with open(filepath, "wb") as f:
FileNotFoundError: [Errno 2] No such file or directory: 'attachments/test.txt'
[2024-02-22T03:48:49.328+0000] {taskinstance.py:1138} INFO - Marking task as FAILED. dag_id=extract_email, task_id=get_mail, execution_date=20240222T034836, start_date=20240222T034840, end_date=20240222T034849
[2024-02-22T03:48:49.358+0000] {standard_task_runner.py:107} ERROR - Failed to execute job 306 for task get_mail ([Errno 2] No such file or directory: 'attachments/test.txt'; 346)
[2024-02-22T03:48:49.377+0000] {local_task_job_runner.py:234} INFO - Task exited with return code 1
[2024-02-22T03:48:49.406+0000] {taskinstance.py:3280} INFO - 0 downstream tasks scheduled from follow-on schedule check
