[2024-02-21T08:06:48.873+0000] {taskinstance.py:1956} INFO - Dependencies all met for dep_context=non-requeueable deps ti=<TaskInstance: extract_email.get_mail scheduled__2024-02-18T01:00:00+00:00 [queued]>
[2024-02-21T08:06:48.886+0000] {taskinstance.py:1956} INFO - Dependencies all met for dep_context=requeueable deps ti=<TaskInstance: extract_email.get_mail scheduled__2024-02-18T01:00:00+00:00 [queued]>
[2024-02-21T08:06:48.886+0000] {taskinstance.py:2170} INFO - Starting attempt 1 of 1
[2024-02-21T08:06:48.901+0000] {taskinstance.py:2191} INFO - Executing <Task(PythonOperator): get_mail> on 2024-02-18 01:00:00+00:00
[2024-02-21T08:06:48.908+0000] {standard_task_runner.py:60} INFO - Started process 192 to run task
[2024-02-21T08:06:48.911+0000] {standard_task_runner.py:87} INFO - Running: ['***', 'tasks', 'run', 'extract_email', 'get_mail', 'scheduled__2024-02-18T01:00:00+00:00', '--job-id', '199', '--raw', '--subdir', 'DAGS_FOLDER/extract_email.py', '--cfg-path', '/tmp/tmpmh6b_5db']
[2024-02-21T08:06:48.913+0000] {standard_task_runner.py:88} INFO - Job 199: Subtask get_mail
[2024-02-21T08:06:48.953+0000] {task_command.py:423} INFO - Running <TaskInstance: extract_email.get_mail scheduled__2024-02-18T01:00:00+00:00 [running]> on host 96f19b77385b
[2024-02-21T08:06:49.020+0000] {taskinstance.py:2480} INFO - Exporting env vars: AIRFLOW_CTX_DAG_OWNER='***' AIRFLOW_CTX_DAG_ID='extract_email' AIRFLOW_CTX_TASK_ID='get_mail' AIRFLOW_CTX_EXECUTION_DATE='2024-02-18T01:00:00+00:00' AIRFLOW_CTX_TRY_NUMBER='1' AIRFLOW_CTX_DAG_RUN_ID='scheduled__2024-02-18T01:00:00+00:00'
[2024-02-21T08:06:50.722+0000] {taskinstance.py:2698} ERROR - Task failed with exception
Traceback (most recent call last):
  File "/home/airflow/.local/lib/python3.8/site-packages/airflow/models/taskinstance.py", line 433, in _execute_task
    result = execute_callable(context=context, **execute_callable_kwargs)
  File "/home/airflow/.local/lib/python3.8/site-packages/airflow/operators/python.py", line 199, in execute
    return_value = self.execute_callable()
  File "/home/airflow/.local/lib/python3.8/site-packages/airflow/operators/python.py", line 216, in execute_callable
    return self.python_callable(*self.op_args, **self.op_kwargs)
  File "/opt/airflow/dags/extract_email.py", line 16, in get_mail
    mail.authorize(account=os.getenv("GMAIL_ACCOUNT"), password=os.getenv("GMAIL_PASSWORD"))
  File "/home/airflow/.local/lib/python3.8/site-packages/RPA/Email/ImapSmtp.py", line 493, in authorize
    self.authorize_smtp(
  File "/home/airflow/.local/lib/python3.8/site-packages/RPA/Email/ImapSmtp.py", line 404, in authorize_smtp
    self.smtp_conn.login(account, password)
  File "/usr/local/lib/python3.8/smtplib.py", line 737, in login
    (code, resp) = self.auth(
  File "/usr/local/lib/python3.8/smtplib.py", line 640, in auth
    (code, resp) = self.docmd("AUTH", mechanism + " " + response)
  File "/usr/local/lib/python3.8/smtplib.py", line 430, in docmd
    return self.getreply()
  File "/usr/local/lib/python3.8/smtplib.py", line 403, in getreply
    raise SMTPServerDisconnected("Connection unexpectedly closed")
smtplib.SMTPServerDisconnected: Connection unexpectedly closed
[2024-02-21T08:06:50.749+0000] {taskinstance.py:1138} INFO - Marking task as FAILED. dag_id=extract_email, task_id=get_mail, execution_date=20240218T010000, start_date=20240221T080648, end_date=20240221T080650
[2024-02-21T08:06:50.776+0000] {standard_task_runner.py:107} ERROR - Failed to execute job 199 for task get_mail (Connection unexpectedly closed; 192)
[2024-02-21T08:06:50.812+0000] {local_task_job_runner.py:234} INFO - Task exited with return code 1
[2024-02-21T08:06:50.834+0000] {taskinstance.py:3280} INFO - 0 downstream tasks scheduled from follow-on schedule check
[2024-02-21T08:13:03.513+0000] {taskinstance.py:1956} INFO - Dependencies all met for dep_context=non-requeueable deps ti=<TaskInstance: extract_email.get_mail scheduled__2024-02-18T01:00:00+00:00 [queued]>
[2024-02-21T08:13:03.531+0000] {taskinstance.py:1956} INFO - Dependencies all met for dep_context=requeueable deps ti=<TaskInstance: extract_email.get_mail scheduled__2024-02-18T01:00:00+00:00 [queued]>
[2024-02-21T08:13:03.532+0000] {taskinstance.py:2170} INFO - Starting attempt 1 of 1
[2024-02-21T08:13:03.565+0000] {taskinstance.py:2191} INFO - Executing <Task(PythonOperator): get_mail> on 2024-02-18 01:00:00+00:00
[2024-02-21T08:13:03.584+0000] {standard_task_runner.py:60} INFO - Started process 169 to run task
[2024-02-21T08:13:03.590+0000] {standard_task_runner.py:87} INFO - Running: ['***', 'tasks', 'run', 'extract_email', 'get_mail', 'scheduled__2024-02-18T01:00:00+00:00', '--job-id', '230', '--raw', '--subdir', 'DAGS_FOLDER/extract_email.py', '--cfg-path', '/tmp/tmpuxxlueb8']
[2024-02-21T08:13:03.594+0000] {standard_task_runner.py:88} INFO - Job 230: Subtask get_mail
[2024-02-21T08:13:03.743+0000] {task_command.py:423} INFO - Running <TaskInstance: extract_email.get_mail scheduled__2024-02-18T01:00:00+00:00 [running]> on host 968b17b6b013
[2024-02-21T08:13:03.888+0000] {taskinstance.py:2480} INFO - Exporting env vars: AIRFLOW_CTX_DAG_OWNER='***' AIRFLOW_CTX_DAG_ID='extract_email' AIRFLOW_CTX_TASK_ID='get_mail' AIRFLOW_CTX_EXECUTION_DATE='2024-02-18T01:00:00+00:00' AIRFLOW_CTX_TRY_NUMBER='1' AIRFLOW_CTX_DAG_RUN_ID='scheduled__2024-02-18T01:00:00+00:00'
[2024-02-21T08:13:06.368+0000] {taskinstance.py:2698} ERROR - Task failed with exception
Traceback (most recent call last):
  File "/home/airflow/.local/lib/python3.8/site-packages/airflow/models/taskinstance.py", line 433, in _execute_task
    result = execute_callable(context=context, **execute_callable_kwargs)
  File "/home/airflow/.local/lib/python3.8/site-packages/airflow/operators/python.py", line 199, in execute
    return_value = self.execute_callable()
  File "/home/airflow/.local/lib/python3.8/site-packages/airflow/operators/python.py", line 216, in execute_callable
    return self.python_callable(*self.op_args, **self.op_kwargs)
  File "/opt/airflow/dags/extract_email.py", line 16, in get_mail
    mail.authorize(account=os.getenv("GMAIL_ACCOUNT"), password=os.getenv("GMAIL_PASSWORD"))
  File "/home/airflow/.local/lib/python3.8/site-packages/RPA/Email/ImapSmtp.py", line 496, in authorize
    self.authorize_imap(
  File "/home/airflow/.local/lib/python3.8/site-packages/RPA/Email/ImapSmtp.py", line 453, in authorize_imap
    self.imap_conn.login(account, password)
  File "/usr/local/lib/python3.8/imaplib.py", line 603, in login
    raise self.error(dat[-1])
imaplib.IMAP4.error: b'[ALERT] Too many simultaneous connections. (Failure)'
[2024-02-21T08:13:06.391+0000] {taskinstance.py:1138} INFO - Marking task as FAILED. dag_id=extract_email, task_id=get_mail, execution_date=20240218T010000, start_date=20240221T081303, end_date=20240221T081306
[2024-02-21T08:13:06.409+0000] {standard_task_runner.py:107} ERROR - Failed to execute job 230 for task get_mail (b'[ALERT] Too many simultaneous connections. (Failure)'; 169)
[2024-02-21T08:13:06.454+0000] {local_task_job_runner.py:234} INFO - Task exited with return code 1
[2024-02-21T08:13:06.473+0000] {taskinstance.py:3280} INFO - 0 downstream tasks scheduled from follow-on schedule check
[2024-02-21T08:18:05.545+0000] {taskinstance.py:1956} INFO - Dependencies all met for dep_context=non-requeueable deps ti=<TaskInstance: extract_email.get_mail scheduled__2024-02-18T01:00:00+00:00 [queued]>
[2024-02-21T08:18:05.561+0000] {taskinstance.py:1956} INFO - Dependencies all met for dep_context=requeueable deps ti=<TaskInstance: extract_email.get_mail scheduled__2024-02-18T01:00:00+00:00 [queued]>
[2024-02-21T08:18:05.561+0000] {taskinstance.py:2170} INFO - Starting attempt 1 of 1
[2024-02-21T08:18:05.585+0000] {taskinstance.py:2191} INFO - Executing <Task(PythonOperator): get_mail> on 2024-02-18 01:00:00+00:00
[2024-02-21T08:18:05.595+0000] {standard_task_runner.py:60} INFO - Started process 121 to run task
[2024-02-21T08:18:05.598+0000] {standard_task_runner.py:87} INFO - Running: ['***', 'tasks', 'run', 'extract_email', 'get_mail', 'scheduled__2024-02-18T01:00:00+00:00', '--job-id', '265', '--raw', '--subdir', 'DAGS_FOLDER/extract_email.py', '--cfg-path', '/tmp/tmptror7cx6']
[2024-02-21T08:18:05.601+0000] {standard_task_runner.py:88} INFO - Job 265: Subtask get_mail
[2024-02-21T08:18:05.646+0000] {task_command.py:423} INFO - Running <TaskInstance: extract_email.get_mail scheduled__2024-02-18T01:00:00+00:00 [running]> on host 9f5f399fdbe3
[2024-02-21T08:18:05.726+0000] {taskinstance.py:2480} INFO - Exporting env vars: AIRFLOW_CTX_DAG_OWNER='***' AIRFLOW_CTX_DAG_ID='extract_email' AIRFLOW_CTX_TASK_ID='get_mail' AIRFLOW_CTX_EXECUTION_DATE='2024-02-18T01:00:00+00:00' AIRFLOW_CTX_TRY_NUMBER='1' AIRFLOW_CTX_DAG_RUN_ID='scheduled__2024-02-18T01:00:00+00:00'
[2024-02-21T08:18:08.061+0000] {taskinstance.py:2698} ERROR - Task failed with exception
Traceback (most recent call last):
  File "/home/airflow/.local/lib/python3.8/site-packages/airflow/models/taskinstance.py", line 433, in _execute_task
    result = execute_callable(context=context, **execute_callable_kwargs)
  File "/home/airflow/.local/lib/python3.8/site-packages/airflow/operators/python.py", line 199, in execute
    return_value = self.execute_callable()
  File "/home/airflow/.local/lib/python3.8/site-packages/airflow/operators/python.py", line 216, in execute_callable
    return self.python_callable(*self.op_args, **self.op_kwargs)
  File "/opt/airflow/dags/extract_email.py", line 16, in get_mail
    mail.authorize(account=os.getenv("GMAIL_ACCOUNT"), password=os.getenv("GMAIL_PASSWORD"))
  File "/home/airflow/.local/lib/python3.8/site-packages/RPA/Email/ImapSmtp.py", line 496, in authorize
    self.authorize_imap(
  File "/home/airflow/.local/lib/python3.8/site-packages/RPA/Email/ImapSmtp.py", line 453, in authorize_imap
    self.imap_conn.login(account, password)
  File "/usr/local/lib/python3.8/imaplib.py", line 603, in login
    raise self.error(dat[-1])
imaplib.IMAP4.error: b'[ALERT] Too many simultaneous connections. (Failure)'
[2024-02-21T08:18:08.068+0000] {taskinstance.py:1138} INFO - Marking task as FAILED. dag_id=extract_email, task_id=get_mail, execution_date=20240218T010000, start_date=20240221T081805, end_date=20240221T081808
[2024-02-21T08:18:08.079+0000] {standard_task_runner.py:107} ERROR - Failed to execute job 265 for task get_mail (b'[ALERT] Too many simultaneous connections. (Failure)'; 121)
[2024-02-21T08:18:08.096+0000] {local_task_job_runner.py:234} INFO - Task exited with return code 1
[2024-02-21T08:18:08.108+0000] {taskinstance.py:3280} INFO - 0 downstream tasks scheduled from follow-on schedule check
