[2024-02-21T07:59:16.176+0000] {taskinstance.py:1956} INFO - Dependencies all met for dep_context=non-requeueable deps ti=<TaskInstance: extract_email.get_mail scheduled__2024-01-12T00:00:00+00:00 [queued]>
[2024-02-21T07:59:16.185+0000] {taskinstance.py:1956} INFO - Dependencies all met for dep_context=requeueable deps ti=<TaskInstance: extract_email.get_mail scheduled__2024-01-12T00:00:00+00:00 [queued]>
[2024-02-21T07:59:16.185+0000] {taskinstance.py:2170} INFO - Starting attempt 1 of 1
[2024-02-21T07:59:16.196+0000] {taskinstance.py:2191} INFO - Executing <Task(PythonOperator): get_mail> on 2024-01-12 00:00:00+00:00
[2024-02-21T07:59:16.200+0000] {standard_task_runner.py:60} INFO - Started process 325 to run task
[2024-02-21T07:59:16.202+0000] {standard_task_runner.py:87} INFO - Running: ['***', 'tasks', 'run', 'extract_email', 'get_mail', 'scheduled__2024-01-12T00:00:00+00:00', '--job-id', '110', '--raw', '--subdir', 'DAGS_FOLDER/extract_email.py', '--cfg-path', '/tmp/tmpe5jgxm_x']
[2024-02-21T07:59:16.204+0000] {standard_task_runner.py:88} INFO - Job 110: Subtask get_mail
[2024-02-21T07:59:16.239+0000] {task_command.py:423} INFO - Running <TaskInstance: extract_email.get_mail scheduled__2024-01-12T00:00:00+00:00 [running]> on host 9bab6a0db245
[2024-02-21T07:59:16.299+0000] {taskinstance.py:2480} INFO - Exporting env vars: AIRFLOW_CTX_DAG_OWNER='***' AIRFLOW_CTX_DAG_ID='extract_email' AIRFLOW_CTX_TASK_ID='get_mail' AIRFLOW_CTX_EXECUTION_DATE='2024-01-12T00:00:00+00:00' AIRFLOW_CTX_TRY_NUMBER='1' AIRFLOW_CTX_DAG_RUN_ID='scheduled__2024-01-12T00:00:00+00:00'
[2024-02-21T07:59:18.386+0000] {taskinstance.py:2698} ERROR - Task failed with exception
Traceback (most recent call last):
  File "/home/airflow/.local/lib/python3.8/site-packages/airflow/models/taskinstance.py", line 433, in _execute_task
    result = execute_callable(context=context, **execute_callable_kwargs)
  File "/home/airflow/.local/lib/python3.8/site-packages/airflow/operators/python.py", line 199, in execute
    return_value = self.execute_callable()
  File "/home/airflow/.local/lib/python3.8/site-packages/airflow/operators/python.py", line 216, in execute_callable
    return self.python_callable(*self.op_args, **self.op_kwargs)
  File "/opt/airflow/dags/extract_email.py", line 16, in get_mail
    mail.authorize(account=os.getenv("GMAIL_ACCOUNT"), password=os.getenv("GMAIL_PASSWORD"))
  File "/home/airflow/.local/lib/python3.8/site-packages/RPA/Email/ImapSmtp.py", line 496, in authorize
    self.authorize_imap(
  File "/home/airflow/.local/lib/python3.8/site-packages/RPA/Email/ImapSmtp.py", line 453, in authorize_imap
    self.imap_conn.login(account, password)
  File "/usr/local/lib/python3.8/imaplib.py", line 603, in login
    raise self.error(dat[-1])
imaplib.IMAP4.error: b'[ALERT] Too many simultaneous connections. (Failure)'
[2024-02-21T07:59:18.395+0000] {taskinstance.py:1138} INFO - Marking task as FAILED. dag_id=extract_email, task_id=get_mail, execution_date=20240112T000000, start_date=20240221T075916, end_date=20240221T075918
[2024-02-21T07:59:18.407+0000] {standard_task_runner.py:107} ERROR - Failed to execute job 110 for task get_mail (b'[ALERT] Too many simultaneous connections. (Failure)'; 325)
[2024-02-21T07:59:18.422+0000] {local_task_job_runner.py:234} INFO - Task exited with return code 1
[2024-02-21T07:59:18.448+0000] {taskinstance.py:3280} INFO - 0 downstream tasks scheduled from follow-on schedule check
